Workbook

Sheet ItemDataTable
A1: ID | B1: Name | C1: Type | D1: BasicPrice | E1: Stack | F1: MaxCapacity | G1: StoragePeriod | H1: UseToDemo
A2: 1011 | B2: CornSeed | C2: Seed | D2: =D3*90/100 -> 900 | E2: 45 | F2: 0 | G2: -1 | H2: 0
A3: 1012 | B3: Corn | C3: Product | D3: 1000 | E3: 9 | F3: 0 | G3: 30 | H3: 0
A4: 1021 | B4: PotatoSeed | C4: Seed | D4: 800 | E4: 45 | F4: 0 | G4: -1 | H4: 1
A5: 1022 | B5: Potato | C5: Product | D5: 900 | E5: 9 | F5: 0 | G5: 30 | H5: 1
A6: 2011 | B6: CarrotSeed | C6: Seed | D6: =D7*90/100 -> 900 | E6: 45 | F6: 0 | G6: -1 | H6: 1
A7: 2012 | B7: Carrot | C7: Product | D7: 1000 | E7: 9 | F7: 0 | G7: 20 | H7: 1
A8: 2021 | B8: OnionSeed | C8: Seed | D8: =D9*90/100 -> 990 | E8: 45 | F8: 0 | G8: -1 | H8: 0
A9: 2022 | B9: Onion | C9: Product | D9: 1100 | E9: 9 | F9: 0 | G9: 20 | H9: 0
A10: 3011 | B10: StrawberrySeed | C10: Seed | D10: 1100 | E10: 45 | F10: 0 | G10: -1 | H10: 1
A11: 3012 | B11: Strawberry | C11: Product | D11: 1200 | E11: 9 | F11: 0 | G11: 15 | H11: 1
A12: 3021 | B12: BlueBerrySeed | C12: Seed | D12: =D13*90/100 -> 990 | E12: 45 | F12: 0 | G12: -1 | H12: 0
A13: 3022 | B13: BlueBerry | C13: Product | D13: 1100 | E13: 9 | F13: 0 | G13: 15 | H13: 0
A14: 4011 | B14: Bottle | C14: Material | D14: 5000 | E14: 8 | F14: 0 | G14: -1 | H14: 1
A15: 4012 | B15: Milk | C15: Product | D15: 5000 | E15: 4 | F15: 0 | G15: 7 | H15: 1
A16: 5001 | B16: Water | C16: Water | D16: 0 | E16: 99 | F16: 0 | G16: -1 | H16: 1
A17: 5011 | B17: 100000G | C17: Developer | D17: 0 | E17: 1 | F17: 0 | G17: -1 | H17: 1
A18: 5021 | B18: ObjectPackage | C18: Tutorial | D18: 0 | E18: 1 | F18: 0 | G18: -1 | H18: 1
A19: 6021 | B19: Prototype | C19: Object | D19: 10000 | E19: 1 | F19: 0 | G19: -1 | H19: 1
A20: 6031 | B20: Cow | C20: Object | D20: 20000 | E20: 1 | F20: 0 | G20: -1 | H20: 1
A21: 6032 | B21: Sheep | C21: Object | D21: 5000 | E21: 1 | F21: 0 | G21: -1 | H21: 0
A22: 7011 | B22: BatteryLv1 | C22: Battery | D22: 1000 | E22: 1 | F22: 300 | G22: -1 | H22: 1
A23: 8011 | B23: MainInvLv1 | C23: UpgPerk | D23: 10000 | E23: 1 | F23: 0 | G23: -1 | H23: 1
A24: 8012 | B24: MainInvLv2 | C24: UpgPerk | D24: 20000 | E24: 1 | F24: 0 | G24: -1 | H24: 0
... A33: 9021 | B33: Barn | C33: BuildingKit | D33: 30000 | E33: 1 | F33: 0 | G33: -1 | H33: 1

Sheet ItemDataTable_Meta
A1: Column | B1: Description | C1: Type
A2: {=TRANSPOSE(ItemDataTable!A1:G1)} -> ID | B2: 아이템 일련번호 | C2: int
A3: Name | B3: 아이템 이름 | C3: string
A4: Type | B4: 아이템 분류 타입(Seed, Product, Kit 등) | C4: enum
A5: BasicPrice | B5: 아이템 기준 가격, 원가 | C5: int
A6: Stack | B6: 한 슬롯에 쌓을 수 있는 최대 아이템 수량 | C6: int
A7: MaxCapacity | B7: 아이템 보관 기간(일 단위, -1은 영구 보관) | C7: int
A8: StoragePeriod

Sheet ProductDataTable
A1: ID | B1: Name | C1: Type | D1: PriceStdDev | E1: GrowthTime | F1: MaxYield | G1: MinYield
A2: 1012 | B2: =VLOOKUP(A2, ItemDataTable!A:B, 2, FALSE) -> Corn | C2: =VLOOKUP(A2, ItemDataTable!A:C,3,FALSE) -> Product | D2: 0.02 | E2: 1 | F2: 1 | G2: 1
A3: 1022 | B3: =VLOOKUP(A3, ItemDataTable!A:B, 2, FALSE) -> Potato | C3: =VLOOKUP(A3, ItemDataTable!A:C,3,FALSE) -> Product | D3: 0.01 | E3: 60 | F3: 1 | G3: 1
A4: 2012 | B4: =VLOOKUP(A4, ItemDataTable!A:B, 2, FALSE) -> Carrot | C4: =VLOOKUP(A4, ItemDataTable!A:C,3,FALSE) -> Product | D4: 0.04 | E4: 120 | F4: 1 | G4: 1
A5: 2022 | B5: =VLOOKUP(A5, ItemDataTable!A:B, 2, FALSE) -> Onion | C5: =VLOOKUP(A5, ItemDataTable!A:C,3,FALSE) -> Product | D5: 0.05 | E5: 1 | F5: 1 | G5: 1
A6: 3012 | B6: =VLOOKUP(A6, ItemDataTable!A:B, 2, FALSE) -> Strawberry | C6: =VLOOKUP(A6, ItemDataTable!A:C,3,FALSE) -> Product | D6: 0.08 | E6: 300 | F6: 1 | G6: 1
A7: 3022 | B7: =VLOOKUP(A7, ItemDataTable!A:B, 2, FALSE) -> BlueBerry | C7: =VLOOKUP(A7, ItemDataTable!A:C,3,FALSE) -> Product | D7: 0.07 | E7: 1 | F7: 1 | G7: 1
A8: 4012 | B8: =VLOOKUP(A8, ItemDataTable!A:B, 2, FALSE) -> Milk | C8: =VLOOKUP(A8, ItemDataTable!A:C,3,FALSE) -> Product | D8: 0.2 | E8: -1 | F8: 1 | G8: 1

Sheet ProductDataTable_Meta
A1: Column | B1: Description | C1: Type
A2: {=TRANSPOSE(ProductDataTable!A1:I1)} -> ID | B2: 아이템 일련번호 | C2: int
A3: Name | B3: 아이템 이름 | C3: string
A4: Type | B4: 아이템 분류 타입 | C4: enum
A5: PriceStdDev | B5: 가격 변동 표준편차 | C5: float
A6: GrowthTime | B6: 원가 | C6: int
A7: MaxYield | B7: 성장 시간 | C7: int
A8: MinYield | B8: 최대 수확량 | C8: int
A9: 0 | B9: 최소 수확량 | C9: int
A10: 0 | B10: 수분 소모량 | C10: int

Sheet ObjectDataTable
A1: ID | B1: Name | C1: Type | D1: MainInv | E1: SubInv | F1: Speed | G1: WorkDuration | H1: DailyYield | I1: YieldCoolDown | J1: YieldMaterial | K1: YieldItem
A2: 6011 | B2: Player | C2: PC | D2: 5 | E2: 3 | F2: 1 | G2: 10 | H2: 0 | I2: 0 | J2: -1 | K2: -1
A3: 6021 | B3: Prototype | C3: NPC | D3: 10 | E3: 1 | F3: 4 | G3: 6 | H3: 0 | I3: 0 | J3: -1 | K3: -1
A4: 6031 | B4: Cow | C4: Cattle | D4: 0 | E4: 0 | F4: 6 | G4: 0 | H4: 2 | I4: 6 | J4: 4011 | K4: 4012
A5: 6032 | B5: Sheep | C5: Cattle | D5: 0 | E5: 0 | F5: 3 | G5: 0 | H5: 1 | I5: 12 | J5: -1 | K5: -1

Sheet ObjectDataTable_Meta
A1: Column | B1: Description | C1: Type
A2: {=TRANSPOSE(ObjectDataTable!A1:I1)} -> ID | B2: 오브젝트 일련번호 | C2: int
A3: Name | B3: 오브젝트 이름 | C3: string
A4: Type | B4: 오브젝트 분류 타입(PC, NPC 등) | C4: enum
A5: MainInv | B5: 오브젝트 구매 가격 | C5: int
A6: SubInv | B6: 오브젝트의 메인 인벤토리 기본 수량 | C6: int
A7: Speed | B7: 오브젝트의 서브 인벤토리 기본 수량 | C7: int
A8: WorkDuration | B8: 오브젝트가 한 칸 이동할 때 걸리는 시간(초) | C8: float
A9: DailyYield | B9: 오브젝트가 일을 할 때 걸리는 시간(초) | C9: float
A10: YieldCoolDown | B10: 오브젝트가 하루동안 생산할 수 있는 아이템 수량 | C10: int

Sheet EventDataTable
A1: ID | B1: Type | C1: Average | D1: Linkage | E1: Text
A2: 101 | B2: DemandIncrease | C2: 0.01 | D2: 0 | E2: {ItemName}의 수요가 일시적으로 증가한 것으로 보입니다.
A3: 102 | B3: DemandDecrease | C3: -0.01 | D3: 0 | E3: {ItemName}의 수요가 일시적으로 감소한 것으로 보입니다.
A4: 103 | B4: DemandSurge | C4: 0.03 | D4: 0 | E4: {ItemName}의 수요가 급격히 증가했습니다.
A5: 104 | B5: DemandCollapse | C5: -0.03 | D5: 0 | E5: {ItemName}의 수요가 급격히 감소했습니다.
A6: 105 | B6: DemandIExplosion | C6: 0.05 | D6: 0 | E6: 폭발적인 반응과 함께 {ItemName}의 수요도 폭발하고 있습니다.
A7: 106 | B7: DemandCrash | C7: -0.05 | D7: 0 | E7: 무슨 일인지 {ItemName}의 수요가 폭락하였습니다.
A8: 201 | B8: DiseaseOutbreak | C8: -0.03 | D8: 0 | E8: 식품 연구소에서 온 보도인데요, 유해할 수 있는 병원균이 아가레아산 {ItemName}에서 발견되었다는 소식 입니다.
A9: 202 | B9: DiseaseUnderControl | C9: 0.01 | D9: 201 | E9: 아가레아산 {ItemName}에서 발견되었다는 병원균에 대한 연구가 꾸준히 이루어지고 있습니다.
A10: 203 | B10: DiseaseContained | C10: 0.02 | D10: 202 | E10: 드디어 {ItemName}의 병원균 백신 개발이 성공적으로 이루어졌습니다.
A11: 211 | B11: PoorHarvest | C11: 0.05 | D11: 0 | E11: 흉작으로 인해 식량 부족 위기라는 보도입니다.
A12: 212 | B12: GoodHarvest | C12: -0.05 | D12: 0 | E12: 풍작으로 인해 시장에 식량이 많이 모였습니다.
A13: 213 | B13: AgriculturalStrike | C13: 0.03 | D13: 0 | E13: 농업 단체에서 집단 파업이 발생했습니다.
... A20: 312 | B20: HarvestDrive | C20: -0.03 | D20: 0 | E20: 청년들의 지원 사업으로 {ItemName}의 생산량이 크게 증가했습니다.

Sheet KeycodeDataTable
A1: ID | B1: Name | C1: Type | D1: DefaultKeyCode | E1: Modifier1 | F1: Modifier2 | G1: IsRebindable | H1: Description_KR
A2: 11 | B2: PC_Movement | C2: Movement | D2: Mouse0 | E2: None | F2: None | G2: 0 | H2: 상호작용
A3: 12 | B3: PC_Interaction | C3: Interaction | D3: Mouse1 | E3: None | F3: None | G3: 0 | H3: 이동
A4: 13 | B4: PC_MoveUp | C4: Movement | D4: W | E4: None | F4: None | G4: 1 | H4: 위로 이동
A5: 14 | B5: PC_MoveLeft | C5: Movement | D5: A | E5: None | F5: None | G5: 1 | H5: 왼쪽으로 이동
A6: 15 | B6: PC_MoveDown | C6: Movement | D6: S | E6: None | F6: None | G6: 1 | H6: 아래로 이동
A7: 16 | B7: PC_MoveRight | C7: Movement | D7: D | E7: None | F7: None | G7: 1 | H7: 오른쪽으로 이동
A8: 21 | B8: PopUp_Chart | C8: UI | D8: C | E8: None | F8: None | G8: 1 | H8: 차트
A9: 22 | B9: PopUp_Shop | C9: UI | D9: M | E9: None | F9: None | G9: 1 | H9: 상점
A10: 23 | B10: PopUp_Robot | C10: UI | D10: R | E10: None | F10: None | G10: 1 | H10: 로봇 관리
A11: 24 | B11: PopUp_Storage | C11: UI | D11: E | E11: None | F11: None | G11: 1 | H11: 창고
A12: 25 | B12: PopUp_Hydro | C12: UI | D12: H | E12: None | F12: None | G12: 1 | H12: 하이드로 리엑터
A13: 29 | B13: PopUp_Setting | C13: UI | D13: Escape | E13: None | F13: None | G13: 0 | H13: 설정
A14: 41 | B14: Select_Slot1 | C14: Selection | D14: 1 | E14: None | F14: None | G14: 1 | H14: 1번 슬롯
A15: 42 | B15: Select_Slot2 | C15: Selection | D15: 2 | E15: None | F15: None | G15: 1 | H15: 2번 슬롯
A16: 43 | B16: Select_Slot3 | C16: Selection | D16: 3 | E16: None | F16: None | G16: 1 | H16: 3번 슬롯

Sheet LocalizationTable
A1: ID | B1: Name | C1: Korean
A2: 1011 | B2: CornSeed | C2: 옥수수 씨앗
A3: 1012 | B3: Corn | C3: 옥수수
A4: 1021 | B4: PotatoSeed | C4: 씨 감자
A5: 1022 | B5: Potato | C5: 감자
A6: 2011 | B6: CarrotSeed | C6: 당근 씨앗
A7: 2012 | B7: Carrot | C7: 당근
A8: 2021 | B8: OnionSeed | C8: 양파 씨앗
A9: 2022 | B9: Onion | C9: 양파
A10: 3011 | B10: StrawberrySeed | C10: 딸기 씨앗
A11: 3012 | B11: Strawberry | C11: 딸기
A12: 3021 | B12: BlueBerrySeed | C12: 블구베리 씨앗
A13: 3022 | B13: BlueBerry | C13: 블루베리
... A33: 9021 | B33: Barn | C33: 축사

Sheet Calculator
A1: 아이템 ID 값을 입력하여 계산 ID값은 2로 끝나는 작물 아이템이어야 한다.
A3: 아이템 ID | B3: 아이템명 | C3: 씨앗 가격 | D3: 기본 가격 | E3: 표준편차 | F3: 평균회귀 기준 하한가
A4: 4012 | B4: =VLOOKUP(A4, ItemDataTable!A:B, 2, FALSE) -> Milk | C4: =VLOOKUP(A4-1, ItemDataTable!A:D, 4, FALSE) -> 5000 | D4: =VLOOKUP(A4, ProductDataTable!A:E,5, FALSE) -> -1 | E4: =VLOOKUP(A4, ProductDataTable!A:E,4, FALSE) -> 0.2 | F4: =D4*(1-(E4*2)) -> -0.6
C6: =1000/100*90 -> 900 | D6: 1000 | E6: 0.06 | F6: =D6*(1-(E6*2)) -> 880

Sheet BIC_ScenarioDataTable
A1: SynarioID | B1: Category | C1: Speaker | D1: Text | E1: TargetUI | F1: Description
A2: 100001 | B2: Basic_BIC | C2: 루크 | D2: 안녕하세요. 프로토타입 오토팜의 담당자 루크입니다.
A3: 100002 | B3: Basic_BIC | C3: 루크 | D3: 플레이어님의 쾌적하고 안전한 아가레아 생활을 위해 각종 수칙들을 설명드리도록 하겠습니다.
A4: 100003 | B4: Basic_BIC | C4: 루크 | D4: 튜토리얼 도중에 그만 건너뛰고 싶으시다면 ESC버튼을 꾹 눌러보세요.
A5: 110001 | B5: Tutorial_BIC_Manual | C5: 루크 | D5: 그러면 우선 간단한 조작 방법부터 설명드리겠습니다.
A6: 110002 | B6: Tutorial_BIC_Manual | C6: 루크 | D6: 화면에 반짝이는 타일에 우클릭을 해보세요. | F6: 플레이어 좌측으로 두 칸 떨어진 위치의 타일에 반짝이는 효과
A7: 110003 | B7: Tutorial_BIC_Manual | C7: 루크 | D7: 지금처럼 원하는 타일에 우클릭을 하면 그 위치로 이동을 할 수 있습니다.
A8: 110004 | B8: Tutorial_BIC_Manual | C8: 루크 | D8: 카메라는 캐릭터를 따라가지 않습니다. 커서를 화면 끝으로 이동시키면 그 방향으로 이동하죠.
A9: 110005 | B9: Tutorial_BIC_Manual | C9: 루크 | D9: 다음으로 반짝이는 건물에 좌클릭을 해보세요.
A10: 110006 | B10: Tutorial_BIC_Manual | C10: 루크 | D10: 원하는 건물이나 캐릭터에 좌클릭을 하면 상호작용을 할 수 있습니다.
A11: 110007 | B11: Tutorial_BIC_Manual | C11: 루크 | D11: 상호작용을 하면 지금처럼 오브젝트의 인터페이스가 등장하며 관련된 작업을 할 수 있죠.
A12: 110008 | B12: Tutorial_BIC_HDR | C12: 루크 | D12: 지금 화면은 하이드로 리엑터라고 하는 건물의 인터페이스입니다. 수소 전지를 충전하거나 물을 얻을 수 있는 인터페이스죠. | F12: 물탱크에 클릭 표시
A13: 110009 | B13: Tutorial_BIC_HDR | C13: 루크 | D13: 우선 물탱크에 좌클릭을 해서 물병을 얻어볼까요?
A14: 110010 | B14: Tutorial_BIC_HDR | C14: 루크 | D14: 물병은 사용할 수 있는 아이템이기 때문에 왼 쪽에 3칸짜리 인벤토리에 생성됩니다. 보조 인벤토리라고 부르죠.
A15: 110011 | B15: Tutorial_BIC_HDR | C15: 루크 | D15: 만약 보조 인벤토리가 가득 차 있다면 물탱크를 눌러도 물병을 얻을 수 없으니 조심하세요. | F15: 충전 슬롯 첫 번째 칸에 반짝이는 효과
A16: 110012 | B16: Tutorial_BIC_HDR | C16: 루크 | D16: 이번에는 전지를 충전해봅시다. 오른 쪽 하단 슬롯에 있는 아이템을 표시된 영역에 드래그해보세요.
A17: 110013 | B17: Tutorial_BIC_HDR | C17: 루크 | D17: 수소 전지라는 이름 답게 물을 분해해서 얻은 수소를 채워 넣는 방식으로 충전을 시키죠.
A18: 110014 | B18: Tutorial_BIC_HDR | C18: 루크 | D18: 충전이 끝나면 자동으로 해제가 되니 과충전 걱정은 안하셔도 되겠습니다.
A19: 110015 | B19: Tutorial_BIC_HDR | C19: 루크 | D19: 일일이 단자에 충전시키는 것이 번거롭다면 자동 충전 토글이나 일괄 충전 버튼을 눌러보세요. | F19: 자동/일괄 충전 버튼에 반짝이는 효과
A20: 110016 | B20: Tutorial_BIC_HDR | C20: 루크 | D20: 이제 이 곳에서의 볼일은 끝났으니 나가볼까요? | F20: EXIT버튼에 반짝이는 효과
A21: 110017 | B21: Tutorial_BIC_Build | C21: 루크 | D21: 이제는 일을 시작할 시간입니다. 밭을 먼저 설치해야겠죠? | F21: 건설 버튼에 반짝이는 효과
A22: 110018 | B22: Tutorial_BIC_Build | C22: 루크 | D22: 방금 누르신 버튼은 건축 모드로 들어가는 버튼입니다.
A23: 110019 | B23: Tutorial_BIC_Build | C23: 루크 | D23: 건축 모드에서는 건물을 제외한 다른 캐릭터 오브젝트는 비활성화 처리가 됩니다.
A24: 110020 | B24: Tutorial_BIC_Build | C24: 루크 | D24: 밭을 한 번 눌러보시겠어요? | F24: 건물 "밭" 버튼에 반짝이는 효과
A25: 110021 | B25: Tutorial_BIC_Build | C25: 루크 | D25: 밭을 포함한 원하는 건물을 선택하면 왼 쪽에 그 건물의 크기와 보유하고 있는 건물 키트의 개수를 확인할 수 있습니다.
A26: 110022 | B26: Tutorial_BIC_Build | C26: 루크 | D26: 밭 같은 경우는 단순히 땅을 갈기만 하면 되기 때문에 키트는 필요 없이 무한으로 표시가 되죠.
A27: 110023 | B27: Tutorial_BIC_Build | C27: 루크 | D27: 자 그러면 표시된 영역에 밭을 설치해 볼까요? | F27: 밭 설치 영역에 반짝이는 효과
A28: 110024 | B28: Tutorial_BIC_Build | C28: 루크 | D28: 잘 하셨습니다. 이번에는 소를 키울 축사도 하나 만들어 볼까요? | F28: 건물 "축사"버튼에 반짝이는 효과
A29: 110025 | B29: Tutorial_BIC_Build | C29: 루크 | D29: 이번에는 원하는 위치에 설치를 해보세요. 밭이나 이미 다른 건물이 있는 위치에는 설치하지 못합니다.
A30: 110026 | B30: Tutorial_BIC_Build | C30: 루크 | D30: 축사 같이 키트를 소모해야 하는 건물은 설치한 영역에 부지가 먼저 생성이 됩니다.
A31: 110027 | B31: Tutorial_BIC_Build | C31: 루크 | D31: 지금처럼 키트가 있는 경우에는 즉시 설치가 진행이 되지만, 키트가 없다면 구매를 해서 수령할 때 까지 기다려야 하죠.
A32: 110028 | B32: Tutorial_BIC_Build | C32: 루크 | D32: 이제 건축 모드를 종료해보죠. | F32: 건축 모드 종료 버튼에 반짝이는 효과
A33: 110029 | B33: Tutorial_BIC_PC_Work | C33: 루크 | D33: 먼저 밭에서 일하는 방법을 알려드리겠습니다. {1번} 키를 누르거나 슬롯을 클릭해서 씨감자를 사용할 준비를 해볼까요? | F33: 보조 인벤토리 1번 슬롯에 반짝이는 효과
A34: 110030 | B34: Tutorial_BIC_PC_Work | C34: 루크 | D34: 이제 빈 밭에 한 칸 씩 상호작용해서 심어봅시다. | F34: 심을 때 마다 한 칸 씩 반짝이는 효과
A35: 110031 | B35: Tutorial_BIC_PC_Work | C35: 루크 | D35: 잘 하셨습니다. 감자가 자라는 시간은 하루 정도 걸리긴 하지만… 이번만 빠르게 시간을 돌려볼게요. | F35: 모든 감자를 바로 성장시키기
A36: 110032 | B36: Tutorial_BIC_PC_Work | C36: 루크 | D36: 자, 다 자란 감자들을 하나 씩 클릭해서 수확해보죠. | F36: 수확할 때 마다 한 칸 씩 반짝이는 효과
A37: 110033 | B37: Tutorial_BIC_PC_Work | C37: 루크 | D37: 수확을 한 아이템은 모두 가운데에 있는 메인 인벤토리 슬롯에 저장됩니다.
A38: 110034 | B38: Tutorial_BIC_PC_Work | C38: 루크 | D38: 그리고 수확을 한 시점을 기준으로 유통기한이 생기게 됩니다. 유통기한 안에 판매를 하지 않으면 썩어서 없어지게 되니 조심하세요.
A39: 110035 | B39: Tutorial_BIC_PC_Work | C39: 루크 | D39: 밭에는 처음 만들 때는 수분이 가득했지만, 한 번 수확을 마치면 밭이 마르게 됩니다.
A40: 110036 | B40: Tutorial_BIC_PC_Work | C40: 루크 | D40: 밭이 마른 경우에는 방금 얻은 물병의 물을 사용해 적셔줘야 합니다. 밭에 사용해보세요.
...

Sheet ConfigDataTable
A1: {=TRANSPOSE(_xlfn.DROP(_xlfn._xlws.FILTER(ConfigDataTable_Edit!A:B, ConfigDataTable_Edit!A:A<>""), 1))} -> UsedBatteryPerWork | B1: RealTimePerDay | C1: DaysPerYear | D1: DaysPerMonth | E1: RocketSlotAmount | F1: RocketDeliveryTime | G1: RocketLoadingTime | H1: BadEndGraceDays | I1: GraceInterest | J1: MarketOpenHour | K1: MarketCloseHour | L1: EventProb | M1: RumorProb | N1: RumorStdMul | O1: FollowUpDecay | P1: FollowUpOverMeanMul | Q1: EmgProb | R1: EmgMinDays | S1: EmgMaxDays | T1: EmgCoolDownDays | U1: EmgAfterLockReachDays | V1: EmgAfterLockExpireDays | W1: EmgLockDecay | X1: EmgVirtualLineMul | Y1: EmgVirtualLineKeepDays | Z1: RegressionRangeMin | AA1: RegressionRangeMax | AB1: LineSampleDays | AC1: LineSettleDays | AD1: LineBinSigma | AE1: LineMinSamples | AF1: LineBlockDecay | AG1: LineQuietPower | AH1: TaxPeriodDays | AI1: EndingGoalMoney | AJ1: StartingPotatoSeed | AK1: StartingPotato | AL1: StartingNPC | AM1: StartingMoney | AN1: ExpireWarningDays | AO1: TimeScaleStep | AP1: TimeScaleMax | AQ1: UITimeStepMinutes | AR1: FieldMaxExpand
A2: 1 | B2: 600 | C2: 336 | D2: 28 | E2: 16 | F2: 7200 | G2: 7200 | H2: 7 | I2: 0.1 | J2: 9 | K2: 23 | L2: 0.25 | M2: 0.25 | N2: 1.3 | O2: 0.7 | P2: 1.3 | Q2: 0.1 | R2: 7 | S2: 14 | T2: 28 | U2: 10 | V2: 7 | W2: 0.7 | X2: 0.3 | Y2: 7 | Z2: 0.5 | AA2: 2 | AB2: 28 | AC2: 14 | AD2: 0.5 | AE2: 2 | AF2: 0.7 | AG2: 0.3 | AH2: 28 | AI2: 100000000 | AJ2: 9 | AK2: 10 | AL2: 1 | AM2: 10000 | AN2: 1 | AO2: 0.5 | AP2: 2 | AQ2: 10 | AR2: 2

Sheet ConfigDataTable_Edit
A1: Column | B1: Value
A2: UsedBatteryPerWork | B2: 1
A3: RealTimePerDay | B3: 600
A4: DaysPerYear | B4: 336
A5: DaysPerMonth | B5: 28
A6: RocketSlotAmount | B6: 16
A7: RocketDeliveryTime | B7: 7200
A8: RocketLoadingTime | B8: 7200
A9: BadEndGraceDays | B9: 7
A10: GraceInterest | B10: 0.1
A11: MarketOpenHour | B11: 9
A12: MarketCloseHour | B12: 23
A13: EventProb | B13: 0.25
... A45: FieldMaxExpand | B45: 2

Sheet ConfigDataTable_Meta
A1: {=_xlfn.TOCOL(ConfigDataTable_Edit!A:A, 1)} -> Column | B1: Description | C1: Type
A2: UsedBatteryPerWork | B2: 행동 마다 사용되는 베터리 용량 | C2: int
A3: RealTimePerDay | B3: 게임 내 하루의 실제 시간(초 단위) | C3: int
A4: DaysPerYear | B4: 게임 기준 1년 | C4: int
A5: DaysPerMonth | B5: 게임 기준 1달 | C5: int
A6: RocketSlotAmount | B6: 로켓 용량 | C6: int
A7: RocketDeliveryTime | B7: 로켓 이동 시간(초 단위) | C7: int
A8: RocketLoadingTime | B8: 로켓 상하차 시간(초 단위) | C8: int
A9: BadEndGraceDays | B9: 게임 오버 유예 기간(게임 내 일 단위) | C9: int
A10: GraceInterest | B10: 유예 기간 이자 비율 | C10: float
A11: MarketOpenHour | B11: 장 시작 시간(게임 내 시간 단위) | C11: int
A12: MarketCloseHour | B12: 장 마감 시간(게임 내 시간 단위) | C12: int
A13: EventProb | B13: 이벤트 발생 확률 | C13: float
... A45: FieldMaxExpand | B45: 각 방향 별 필드 확장 최대 횟수 | C45: int
